Workbook

Sheet Overview
A1: Architectural NFR and Decision Register
A2: A single owner-editable source of architectural factors, decisions, provenance and selected stack
A4: Architecture Decision Readiness
A5: Grade | B5: Total | C5: Approved | D5: Deferred | E5: In progress | F5: Resolved for Stage 9 | G5: Readiness | H5: Result
A6: A | B6: =COUNTIF('NFR Register'!$A$6:$A$205,A6) -> 16 | C6: =COUNTIFS('NFR Register'!$A$6:$A$205,A6,'NFR Register'!$N$6:$N$205,"Approved",'NFR Register'!$W$6:$W$205,"Yes") -> 0 | D6: =COUNTIFS('NFR Register'!$A$6:$A$205,A6,'NFR Register'!$N$6:$N$205,"Deferred",'NFR Register'!$W$6:$W$205,"Yes") -> 0 | E6: =B6-C6-D6 -> 16 | F6: =C6+D6 -> 0 | G6: =IFERROR(F6/B6,0) -> 0 | H6: =IF(G6=1,"Ready",IF(A6="A","Blocking Stage 9","Continue the survey")) -> Blocking Stage 9
A7: B | B7: =COUNTIF('NFR Register'!$A$6:$A$205,A7) -> 22 | C7: =COUNTIFS('NFR Register'!$A$6:$A$205,A7,'NFR Register'!$N$6:$N$205,"Approved",'NFR Register'!$W$6:$W$205,"Yes") -> 0 | D7: =COUNTIFS('NFR Register'!$A$6:$A$205,A7,'NFR Register'!$N$6:$N$205,"Deferred",'NFR Register'!$W$6:$W$205,"Yes") -> 0 | E7: =B7-C7-D7 -> 22 | F7: =C7+D7 -> 0 | G7: =IFERROR(F7/B7,0) -> 0 | H7: =IF(G7=1,"Ready",IF(A7="A","Blocking Stage 9","Continue the survey")) -> Continue the survey
A8: C | B8: =COUNTIF('NFR Register'!$A$6:$A$205,A8) -> 11 | C8: =COUNTIFS('NFR Register'!$A$6:$A$205,A8,'NFR Register'!$N$6:$N$205,"Approved",'NFR Register'!$W$6:$W$205,"Yes") -> 0 | D8: =COUNTIFS('NFR Register'!$A$6:$A$205,A8,'NFR Register'!$N$6:$N$205,"Deferred",'NFR Register'!$W$6:$W$205,"Yes") -> 0 | E8: =B8-C8-D8 -> 11 | F8: =C8+D8 -> 0 | G8: =IFERROR(F8/B8,0) -> 0 | H8: =IF(G8=1,"Ready",IF(A8="A","Blocking Stage 9","Continue the survey")) -> Continue the survey
A9: Total | B9: =SUM(B6:B8) -> 49 | C9: =SUM(C6:C8) -> 0 | D9: =SUM(D6:D8) -> 0 | E9: =SUM(E6:E8) -> 49 | F9: =SUM(F6:F8) -> 0 | G9: =IFERROR(F9/B9,0) -> 0 | H9: =IF(G6=1,IF(G9=1,"Ready","Grade A is ready."),"Stage 9 is open") -> Stage 9 is open
A11: How does the result count? | E11: The current focus
A12: Solved for Stage 9 = approved + owner-approved deferral with recorded trigger. | E12: Start with the first line open by Grade A and go through it with the owner.
A13: Grade A blocks the next step until all strings are solved and evidence is fixed.
A14: The Grade B and C remain visible production-readiness backlogs.
A17: Workbook Navigator
A18: Priority | B18: Worksheet | D18: What is inside and when to use it
A19: 1 | B19: Overview | D19: The main summary: readiness of decisions on grades, current gate, progress of the questionnaire and navigation on the book.
A20: 2 | B20: Legacy Discovery | D20: Facts about the old system from code, configuration, live walkthrough and interviews; this is evidence, not target decision.
A21: 3 | B21: NFR Register | D21: The main owner-editable registry of NFR and architecture decisions: grade, decision, responsible, status, evidence and the topic of the future slice.
A22: 4 | B22: System Diagram Gate | D22: The minimum set of closed questions, without which it is impossible to approve a high-level system diagram.
A23: 5 | B23: Team Capability | D23: Competences and capacity of the team, confirmed gaps and a plan to close them before implementing the affected slice.
A24: 6 | B24: Technology Stack | D24: Selected, Deferred and Rejected Technologies with Reasoning, Solution Owner, and Communication with NFR/ADR.
A25: 7 | B25: Integration Contracts | D25: Known incoming and outgoing integration contracts, protocols, consumers and open issues.
A26: 8 | B26: Client Questionnaire | D26: Questions that cannot be reliably deduced from legacy evidence and must be confirmed by the client.
A27: 9 | B27: Reference Data | D27: Controlled values and filling rules: grades, statuses, roles, provenance and line closure criteria.

Sheet Legacy Discovery
A1: Legacy Architecture Discovery
A2: We record the architecturally significant facts of the old system before the NFR and the selection of target decision. The list does not contain target design.
A3: Evidence priority: legacy code/config → live walkthrough → client interview. Live verification can only be skipped with a recorded owner decision; a pass is not considered verified live.
A4: Total discovery items | C4: Code review required | E4: Live walkthrough required | G4: Client interview required | I4: Completed | K4: Readiness | M4: live walkthrough
A5: =COUNTA(A8:A26) -> 19 | C5: =COUNTIF(F8:F26,"Required") -> 17 | E5: =COUNTIF(G8:G26,"Required") -> 12 | G5: =COUNTIF(H8:H26,"Required") -> 12 | I5: =COUNTIF(N8:N26,"Completed") -> 0 | K5: =IF(A5=0,0,I5/A5) -> 0 | M5: Only Skipped by Owner with a reason
A6: Stable ID | B6: Legacy area | C6: What to prove before a target decision | D6: Why it affects architecture | E6: Mandatory / conditional / client | F6: We need code analysis. | G6: We need live walkthrough. | H6: client interview. | I6: Code and Configuration Facts | J6: Live Confirmation | K6: Client Input | L6: Consolidated Legacy Behavior | M6: Remaining Unknowns | N6: Discovery Status | O6: Files, Lines, URLs, Reports | P6: Linked Future NFR | Q6: Discovery Owner | R6: Independent Reviewer | S6: Limitations and explanations
A7: ID | B7: Legacy area | C7: What to explore | D7: Why is it relevant? | E7: Discovery requirement | F7: Code review | G7: Live walkthrough | H7: Client interview | I7: Code findings | J7: Live findings | K7: Client input | L7: Current legacy behavior | M7: Unknowns / risks | N7: Verification status | O7: Evidence links | P7: Linked NFR | Q7: Discovery owner | R7: Independent review | S7: Notes
A8: LD-001 | B8: Data and transactions | C8: Find transaction boundaries, consistency model, lock, commit/rollback and related side effects. | D8: Defines targeted transactions, outbox and eventual consistency. | E8: Required | F8: Required | G8: Recommended | H8: Recommended | M8: Unexamined. | N8: Not started. | P8: A06 | S8: The target decision is accepted in the NFR Register.
A9: LD-002 | B9: Session State and Scaling | C9: Where the session state is stored, sticky is the session, which prevents multiple instances of the application. | D9: Determines the stateless model and the possibility of horizontal scaling. | E9: Required | F9: Required | G9: Required | H9: Recommended | M9: Unexamined. | N9: Not started. | P9: A10
A10: LD-003 | B10: Authentication | C10: What login mechanisms, credential stores, session/cookie rules, LDAP/NTLM and logout/timeout exist? | D10: You need to keep working login methods and security semantics. | E10: Required | F10: Required | G10: Required | H10: Required | M10: Unexamined. | N10: Not started. | P10: A11
A11: LD-004 | B11: Authorization and roles | C11: Gather roles, permissions, inheritance, backend/UI checks and the real limitations of each role. | D11: Is evidence for exact parity roles and policy authorization. | E11: Required | F11: Required | G11: Required | H11: Required | M11: Unexamined. | N11: Not started. | P11: A12 | S11: Role research is separate from the target authorization decision.
A12: LD-005 | B12: Product model and tenants | C12: Are there tenants/organizations, how data is isolated and whether a user can relate to multiple tenants? | D12: It defines the multi-tenancy model and data boundaries. | E12: Required | F12: Required | G12: Required | H12: Required | M12: Unexamined. | N12: Not started. | P12: A13
A13: LD-006 | B13: Sensitive data and security controls | C13: Identify sensitive data, encryption, auditing, secrets, and existing security mechanisms that are reasonably provable. | D13: Helps not to lose mandatory security controls; compliance is confirmed by the client. | E13: Conditional | F13: Required | G13: Recommended | H13: Required | M13: Part of the requirements may be known only to the client/security owner | N13: Not started. | P13: A14; B02 | S13: Do not infer compliance only from the code.
A14: LD-007 | B14: External integration | C14: Make a complete catalog of inbound/outbound integrations: HTTP, SOAP, sockets, MQ, files, email, DB and formats. | D14: Defines target integration contracts and backward compatibility. | E14: Required | F14: Required | G14: Required | H14: Required | M14: Unexamined. | N14: Not started. | P14: A15 | S14: The presence of the code does not prove actual use.
A15: LD-008 | B15: Consumers of Integration | C15: Find out what systems and customers are truly integrated, who the owner is, and what contracts cannot be broken. | D15: Separate the available opportunity from the production contract used. | E15: Client-dependent | F15: Recommended | G15: Recommended | H15: Required | M15: client interview required | N15: Not started. | P15: A15 | S15: Required client checkpoint for integrations.
A16: LD-009 | B16: Jobs, workers and schedulers | C16: Find a complete list of scheduled jobs, workers, batch, retries, queues and dormant/background operations. | D16: First inventory, then a separate target solution for the scheduler/worker mechanism. | E16: Required | F16: Required | G16: Required | H16: Recommended | M16: Unexamined. | N16: Not started. | P16: A16 | S16: A16 is not closed without a complete inventory.
A17: LD-010 | B17: Operation and observability | C17: Find logs, metrics, health checks, audit trail, operational endpoints, and real-world diagnostic procedures. | D17: Determine which operational capabilities to maintain or replace. | E17: Required | F17: Required | G17: Recommended | H17: Required | M17: Unexamined. | N17: Not started. | P17: B01
A18: LD-011 | B18: Security operations | C18: Find security audit, lockout, credential rotation, privileged operations, and incident-relevant evidence. | D18: Defines operational security controls of the new system. | E18: Required | F18: Required | G18: Required | H18: Required | M18: Unexamined. | N18: Not started. | P18: B02
A19: LD-012 | B19: Backup and restore | C19: Determine what is copied and how it is restored and verified. | D19: The Backup/restore is a mechanism; the targeted RPO/RTO remains a separate business decision. | E19: Required | F19: Recommended | G19: Recommended | H19: Required | M19: Infrastructure details may not be available in the repository | N19: Not started. | P19: B03; A04 | S19: Do not mix backup with approved RPO/RTO.
A20: LD-013 | B20: File management | C20: Find upload/download/storage, metadata, rights, sizes, lifecycle and external file storage. | D20: Defines target storage adapter, security and migration. | E20: Required | F20: Required | G20: Required | H20: Required | M20: Unexamined. | N20: Not started. | P20: B07
A21: LD-014 | B21: Refusal of external providers | C21: Find timeout, retry, idempotency, fallback, dead-letter/replay and UI behavior when integrations fail. | D21: Determines the reliability of target adapters and user behavior in case of failure. | E21: Required | F21: Required | G21: Required | H21: Recommended | M21: Unexamined. | N21: Not started. | P21: B11
A22: LD-015 | B22: Customization and expansion | C22: Find plugins, overrides, tenant/client customization, white-label hooks and actually used variants. | D22: Extension points and allowable target scope. | E22: Required | F22: Required | G22: Recommended | H22: Required | M22: Distinguish between frameworks and client customizations | N22: Not started. | P22: B14
A23: LD-016 | B23: UI localization | C23: Find languages, resource bundles, fallback, localized labels, directories, and UI formats. | D23: Defines frontend localization contract without reference to a specific UI framework. | E23: Required | F23: Required | G23: Required | H23: Required | M23: Unexamined. | N23: Not started. | P23: A17 | S23: Target stack is not yet selected on this page.
A24: LD-017 | B24: Backend Localization and Errors | C24: Determine whether backend returns ready-made texts, error codes, localized directories, or stable keys. | D24: Defines the boundary between error translation and reference data between backend and UI. | E24: Required | F24: Required | G24: Required | H24: Recommended | M24: Unexamined. | N24: Not started. | P24: A17
A25: LD-018 | B25: Date, time and timezone | C25: Find storage/API/UI formats, timezone semantics, UTC/local dates, and DST behavior. | D25: It defines the temporal contract of a new system and eliminates ambiguous transformations. | E25: Required | F25: Required | G25: Required | H25: Recommended | M25: Unexamined. | N25: Not started. | P25: A17 | S25: Line localization and temporal contract are checked separately.
A26: LD-019 | B26: Messaging, queues and broker | C26: Find MQ/JMS/DB queues, producers/consumers, delivery guarantees, ordering, retry and replay. | D26: Separates message transport from jobs/workers and determines whether a target broker is needed. | E26: Required | F26: Required | G26: Recommended | H26: Recommended | M26: Unexamined. | N26: Not started. | P26: C03; A16 | S26: Job launches the work; broker sends the messages — these are different studies.

Sheet NFR Register
A1: NFR and architecture decisions
A2: The filled fields are highlighted in light yellow. The agent proposes and indicates the source; the decision takes one responsible role, the mandatory participants consult, and the person-approver is recorded separately.
A3: STAGE 9 CURRENT: Grade A decisions are governed in this register. Architecture is revisited after every implemented slice; feature detail stays in downstream delivery specification until code and tests provide evidence.
A4: gate | B4: Grade A is open without owner decision Stage 9 | H4: Grade B: Controlled assumption allowed | O4: Grade C: trigger only, without premature implementation
A5: Grade | B5: ID | C5: Category | D5: Criterion | E5: Question / Decision Needed | F5: Impact | G5: Measurable Target / Decision | H5: Decision Basis | I5: Decision Rationale | J5: Decision Owner | K5: Required Participants | L5: Approved By | M5: Approval Date | N5: Status | O5: Assumption Valid Until | P5: Evidence / Supporting Facts | Q5: Decision record / ADR | R5: Closure Condition | S5: Re-review Trigger | T5: Criterion Source | U5: Proposed by | V5: Proposal / Review Reference | W5: Closed | X5: Architecture Area | Y5: First Dependent Slice | Z5: Where to refine and verify again
A6: A | B6: A01 | C6: The load | D6: Users and loads | E6: How many active users are expected now, at the peak and in 1-3 years? What are normal and peak RPS? | F6: Sizing, scaling model, caching, connection pools, choice of infrastructure | J6: Customer / Product Owner | K6: Solution Architect | N6: Unknown | R6: Approved numbers or explicitly recorded owner-approval | S6: Change of forecast to more than agreed threshold | T6: Both CSVs | U6: Imported; agent not recorded | V6: Both CSVs | W6: =IF(N6="Approved",IF(AND(G6<>"",J6<>"",K6<>"",L6<>"",L6<>"Architect draft",M6<>"",P6<>"",Q6<>""),"Yes","No"),IF(N6="Deferred",IF(AND(I6<>"",J6<>"",L6<>"",L6<>"Architect draft",M6<>"",P6<>"",S6<>""),"Yes","No"),"No")) -> No | X6: Deployment & Operations | Y6: first operational slice that measures or changes this criterion | Z6: Checked as working slices and measurements appear; topology, SLO, or scale changes update NFR/ADR.
A7: A | B7: A02 | C7: Performance | D7: Performance | E7: Which p95/p99 is permissible for reading, writing, searching, reporting, exporting and mass transactions? | F7: APIs, queries, indexes, cache, background operations, CDNs | J7: Customer / Product Owner | K7: Solution Architect | N7: Unknown | R7: There are measurable thresholds and load test scenarios | S7: Violation of the SLO or the emergence of a new heavy script | T7: Both CSVs | U7: Imported; agent not recorded | V7: Both CSVs | W7: =IF(N7="Approved",IF(AND(G7<>"",J7<>"",K7<>"",L7<>"",L7<>"Architect draft",M7<>"",P7<>"",Q7<>""),"Yes","No"),IF(N7="Deferred",IF(AND(I7<>"",J7<>"",L7<>"",L7<>"Architect draft",M7<>"",P7<>"",S7<>""),"Yes","No"),"No")) -> No | X7: Deployment & Operations | Y7: first operational slice that measures or changes this criterion | Z7: Checked as working slices and measurements appear; topology, SLO, or scale changes update NFR/ADR.
A8: A | B8: A03 | C8: Reliability | D8: Availability (SLA/SLO) | E8: What uptime is required? Are scheduled service windows acceptable and how long? | F8: One server or cluster, balancer, rolling/blue-green deployment, cost | J8: Customer / Product Owner | K8: Solution Architect | N8: Unknown | R8: Approved by SLA/SLO or expressly limited demo-SLA | S8: Change to SLA/SLO | T8: Both CSVs | U8: Imported; agent not recorded | V8: Both CSVs | W8: =IF(N8="Approved",IF(AND(G8<>"",J8<>"",K8<>"",L8<>"",L8<>"Architect draft",M8<>"",P8<>"",Q8<>""),"Yes","No"),IF(N8="Deferred",IF(AND(I8<>"",J8<>"",L8<>"",L8<>"Architect draft",M8<>"",P8<>"",S8<>""),"Yes","No"),"No")) -> No | X8: Deployment & Operations | Y8: first operational slice that measures or changes this criterion | Z8: Checked as working slices and measurements appear; topology, SLO, or scale changes update NFR/ADR.
A9: A | B9: A04 | C9: Reliability | D9: RPO and RTO | E9: How much data is allowed to be lost and how long should the system recover from a failure? | F9: Backup, replication, disaster recovery, restore procedure | J9: Customer / Product Owner | K9: Solution Architect | N9: Unknown | R9: Approved by RPO/RTO and method for verifying recovery | S9: Changes in data criticality or SLA | T9: Both CSVs; Grade upgraded to A | U9: Imported; agent not recorded | V9: Both CSVs; Grade upgraded to A | W9: =IF(N9="Approved",IF(AND(G9<>"",J9<>"",K9<>"",L9<>"",L9<>"Architect draft",M9<>"",P9<>"",Q9<>""),"Yes","No"),IF(N9="Deferred",IF(AND(I9<>"",J9<>"",L9<>"",L9<>"Architect draft",M9<>"",P9<>"",S9<>""),"Yes","No"),"No")) -> No | X9: Deployment & Operations | Y9: first operational slice that measures or changes this criterion | Z9: Checked as working slices and measurements appear; topology, SLO, or scale changes update NFR/ADR.
A10: A | B10: A06 | C10: Data | D10: Transaction and coherence | E10: Which operations require strict ACID consistency, and where is eventual consistency allowed? | F10: Transaction boundaries, outbox, CQRS, queues, error and repeat model | J10: Customer / Product Owner | K10: Solution Architect | N10: Unknown | R10: Critical transactions are classified according to the consistency model | S10: New integration or distributed transaction | T10: CSV Claude + Detailing | U10: Claude | V10: CSV Claude + Detailing | W10: =IF(N10="Approved",IF(AND(G10<>"",J10<>"",K10<>"",L10<>"",L10<>"Architect draft",M10<>"",P10<>"",Q10<>""),"Yes","No"),IF(N10="Deferred",IF(AND(I10<>"",J10<>"",L10<>"",L10<>"Architect draft",M10<>"",P10<>"",S10<>""),"Yes","No"),"No")) -> No | X10: Foundation | Y10: 001-solution-foundation | Z10: Grade A captures the system solution. After each implementation, the architecture is checked again; change runtime, data, transactions, tenancy or deployment updates NFR/ADR.
A11: A | B11: A07 | C11: Infrastructure | D11: Location and geography | E11: Where do demo and production work: on-premise, cloud or hybrid? In which regions can data be stored and processed? | F11: Docker Compose, Kubernetes, App Service, network, latency, data residency | J11: Customer / Product Owner | K11: Solution Architect; Operations / DevOps | N11: Unknown | R11: Approved the first platform and geographical restrictions | S11: Change of site, region or model of support | T11: Both CSVs | U11: Imported; agent not recorded | V11: Both CSVs | W11: =IF(N11="Approved",IF(AND(G11<>"",J11<>"",K11<>"",L11<>"",L11<>"Architect draft",M11<>"",P11<>"",Q11<>""),"Yes","No"),IF(N11="Deferred",IF(AND(I11<>"",J11<>"",L11<>"",L11<>"Architect draft",M11<>"",P11<>"",S11<>""),"Yes","No"),"No")) -> No | X11: Deployment & Operations | Y11: 002-demo-deployment-baseline | Z11: Checked as working slices and measurements appear; topology, SLO, or scale changes update NFR/ADR.
A12: A | B12: A08 | C12: Limitations | D12: Budget, timing and TCO | E12: What is the development and operation budget for 3 years, deadline and allowable licensing costs? | F12: Managed services, licenses, level of automation, team size and scope | J12: Customer / Product Owner | K12: Solution Architect; Operations / DevOps | N12: Unknown | R12: Budget and time frames or owner-approval | S12: Change in budget, deadline or platform cost | T12: CSV Claude | U12: Claude | V12: CSV Claude | W12: =IF(N12="Approved",IF(AND(G12<>"",J12<>"",K12<>"",L12<>"",L12<>"Architect draft",M12<>"",P12<>"",Q12<>""),"Yes","No"),IF(N12="Deferred",IF(AND(I12<>"",J12<>"",L12<>"",L12<>"Architect draft",M12<>"",P12<>"",S12<>""),"Yes","No"),"No")) -> No | X12: Deployment & Operations | Y12: first operational slice that measures or changes this criterion | Z12: Checked as working slices and measurements appear; topology, SLO, or scale changes update NFR/ADR.
A13: A | B13: A10 | C13: Architecture | D13: Session state and horizontal scaling | E13: Where is the user and server state stored? Are in-memory sessions and sticky sessions acceptable? Should the API node be replaced without losing user context? | F13: Cookie/session model, shared Data Protection keys, load balancing, fault tolerance and horizontal scale-out | H13: Architecture decision | J13: Customer / Product Owner | K13: Solution Architect; Security / Compliance; Operations / DevOps | N13: Under discussion | R13: The owner has approved the state model; cookie/session boundaries are described; the two-way test does not require sticky sessions. | S13: Server-side session, distributed cache or new availability target | T13: Manager review 2026-08-11 | U13: Manager | V13: Manager notes supplied to Codex, 2026-08-11 | W13: =IF(N13="Approved",IF(AND(G13<>"",J13<>"",K13<>"",L13<>"",L13<>"Architect draft",M13<>"",P13<>"",Q13<>""),"Yes","No"),IF(N13="Deferred",IF(AND(I13<>"",J13<>"",L13<>"",L13<>"Architect draft",M13<>"",P13<>"",S13<>""),"Yes","No"),"No")) -> No | X13: Foundation | Y13: 001-solution-foundation | Z13: Grade A captures the system solution. After each implementation, the architecture is checked again; change runtime, data, transactions, tenancy or deployment updates NFR/ADR.
A14: A | B14: A11 | C14: Security | D14: Authentication | E14: What login methods are needed for web, API and future mobile clients: cookies, OIDC, SSO, LDAP/AD, MFA? | F14: Identity provider, ASP.NET Core Identity, cookie/JWT, gateway | J14: Customer / Product Owner | K14: Solution Architect; Security / Compliance | N14: Unknown | R14: Approved method of entry for each type of client | S14: A new customer or identity provider | T14: Our CSV; Claude has combined | U14: Claude | V14: Our CSV; Claude has combined | W14: =IF(N14="Approved",IF(AND(G14<>"",J14<>"",K14<>"",L14<>"",L14<>"Architect draft",M14<>"",P14<>"",Q14<>""),"Yes","No"),IF(N14="Deferred",IF(AND(I14<>"",J14<>"",L14<>"",L14<>"Architect draft",M14<>"",P14<>"",S14<>""),"Yes","No"),"No")) -> No | X14: Identity & Access | Y14: 003-identity-and-access | Z14: It is specified in the feature/downstream delivery specification. The result is returned to the architecture and, if necessary, updates NFR/ADR..
A15: A | B15: A12 | C15: Security | D15: Authorization | E15: What exact set of legacy roles and permissions exist in the database, code, and live application? What are the specifications of target-only allowed by the owner? | F15: Role model, API policies, Angular hide/disable rules, tenant boundaries, migration Identity data and acceptance tests | H15: Legacy parity | J15: Customer / Product Owner | K15: Solution Architect; Security / Compliance | N15: Under discussion | R15: The role-permission matrix and source of each role are fixed; Draw.io shows roles and trust boundaries; allow/deny tests cover the matrix. | S15: New role, permission, tenant scope or change of legacy authorization behavior | T15: Legacy parity + Manager review 2026-08-11 | U15: Owner / Manager | V15: Manager notes supplied to Codex, 2026-08-11 | W15: =IF(N15="Approved",IF(AND(G15<>"",J15<>"",K15<>"",L15<>"",L15<>"Architect draft",M15<>"",P15<>"",Q15<>""),"Yes","No"),IF(N15="Deferred",IF(AND(I15<>"",J15<>"",L15<>"",L15<>"Architect draft",M15<>"",P15<>"",S15<>""),"Yes","No"),"No")) -> No | X15: Identity & Access | Y15: 003-identity-and-access | Z15: It is specified in the feature/downstream delivery specification. The result is returned to the architecture and, if necessary, updates NFR/ADR..
A16: A | B16: A13 | C16: Product model | D16: The need for multi-tenancy | E16: Does the system serve one organization or several isolated customers? What level of isolation is required? | F16: Tenant model, schema strategy, authorization, billing, deployment | J16: Customer / Product Owner | K16: Solution Architect | N16: Unknown | R16: Early yes/no decision and isolation level determined for yes | S16: Appearance of a SaaS model or new customer | T16: Both CSVs; Early Decision A | U16: Imported; agent not recorded | V16: Both CSVs; Early Decision A | W16: =IF(N16="Approved",IF(AND(G16<>"",J16<>"",K16<>"",L16<>"",L16<>"Architect draft",M16<>"",P16<>"",Q16<>""),"Yes","No"),IF(N16="Deferred",IF(AND(I16<>"",J16<>"",L16<>"",L16<>"Architect draft",M16<>"",P16<>"",S16<>""),"Yes","No"),"No")) -> No | X16: Foundation | Y16: 001-solution-foundation | Z16: Grade A captures the system solution. After each implementation, the architecture is checked again; change runtime, data, transactions, tenancy or deployment updates NFR/ADR.
A17: A | B17: A14 | C17: Security | D17: Data sensitivity and compliance | E17: What PII, financial or other regulated data are stored? What standards, audit, encryption and masking are required? | F17: Encryption, secrets, audit, database access, observability, hosting | J17: Security / Compliance | K17: Solution Architect; Security / Compliance | N17: Unknown | R17: Data classification and a set of mandatory protection measures | S17: New data type, country or regulatory requirement | T17: Both CSVs | U17: Imported; agent not recorded | V17: Both CSVs | W17: =IF(N17="Approved",IF(AND(G17<>"",J17<>"",K17<>"",L17<>"",L17<>"Architect draft",M17<>"",P17<>"",Q17<>""),"Yes","No"),IF(N17="Deferred",IF(AND(I17<>"",J17<>"",L17<>"",L17<>"Architect draft",M17<>"",P17<>"",S17<>""),"Yes","No"),"No")) -> No | X17: Identity & Access | Y17: 003-identity-and-access | Z17: It is specified in the feature/downstream delivery specification. The result is returned to the architecture and, if necessary, updates NFR/ADR..
A18: A | B18: A15 | C18: Integration | D18: Mandatory integration | E18: What systems do you need to interact with, what protocols, and what SLA/delivery guarantees? | F18: REST/gRPC/events, adapter, outbox, retries, circuit breaker, idempotency | J18: Customer / Product Owner | K18: Solution Architect | N18: Unknown | R18: For each integration, a contract, SLA and delivery guarantee are defined. | S18: Adding or modifying an external system | T18: Both CSVs | U18: Imported; agent not recorded | V18: Both CSVs | W18: =IF(N18="Approved",IF(AND(G18<>"",J18<>"",K18<>"",L18<>"",L18<>"Architect draft",M18<>"",P18<>"",Q18<>""),"Yes","No"),IF(N18="Deferred",IF(AND(I18<>"",J18<>"",L18<>"",L18<>"Architect draft",M18<>"",P18<>"",S18<>""),"Yes","No"),"No")) -> No | X18: Integrations & Background Work | Y18: first integration/background-work slice | Z18: It is specified in the feature/downstream delivery specification. Real jobs, retries and contracts are verified after implementation and returned to the architecture.
A19: A | B19: A16 | C19: Background processes | D19: Inventory jobs, workers and background operations | E19: What scheduled jobs, workers, queue consumers and background operations are real and active? How can you give up scheduler/worker without losing behavior? | F19: Scheduler, outbox, worker topology, transaction boundaries, retry/replay, operations and deployment | H19: Legacy parity | J19: Customer / Product Owner | K19: Solution Architect; Operations / DevOps; Technical Lead | N19: Under discussion | R19: Inventory lists every process, activity proof and target mechanism; no unexplained jobs/workers; owner has approved do-not-port/deferred elements. | S19: New background path found, delivery semantics changed or broker/service split appears | T19: Manager review 2026-08-11 | U19: Manager | V19: Manager notes supplied to Codex, 2026-08-11 | W19: =IF(N19="Approved",IF(AND(G19<>"",J19<>"",K19<>"",L19<>"",L19<>"Architect draft",M19<>"",P19<>"",Q19<>""),"Yes","No"),IF(N19="Deferred",IF(AND(I19<>"",J19<>"",L19<>"",L19<>"Architect draft",M19<>"",P19<>"",S19<>""),"Yes","No"),"No")) -> No | X19: Integrations & Background Work | Y19: first integration/background-work slice | Z19: It is specified in the feature/downstream delivery specification. Real jobs, retries and contracts are verified after implementation and returned to the architecture.
A20: A | B20: A18 | C20: Product | D20: Distribution and customer customization | E20: Do all customers get the same build and functionality? Do you need tenant entitlements, configuration-driven customization or feature flags? Are separate client builds acceptable? | F20: Product packaging, tenant configuration, release compatibility, test matrix, support cost and upgrade path | H20: Target-only business requirement | J20: Customer / Product Owner | K20: Solution Architect; Operations / DevOps | N20: Under discussion | R20: The Owner has chosen the distribution model; the tenant differences allowed, the feature-flag policy and the prohibition/rules of individual builds are defined. | S20: New client requires different scope, licensing/entitlement model or independent release cadence | T20: Manager review 2026-08-11 | U20: Manager | V20: Manager notes supplied to Codex, 2026-08-11 | W20: =IF(N20="Approved",IF(AND(G20<>"",J20<>"",K20<>"",L20<>"",L20<>"Architect draft",M20<>"",P20<>"",Q20<>""),"Yes","No"),IF(N20="Deferred",IF(AND(I20<>"",J20<>"",L20<>"",L20<>"Architect draft",M20<>"",P20<>"",S20<>""),"Yes","No"),"No")) -> No | X20: Foundation | Y20: 001-solution-foundation | Z20: Grade A captures the system solution. After each implementation, the architecture is checked again; change runtime, data, transactions, tenancy or deployment updates NFR/ADR.
A21: A | B21: A20 | C21: Migration | D21: The functional parity boundary | E21: What legacy behaviors should be preserved, which can be changed, postponed or excluded? | F21: Scope architecture, downstream delivery specification, cutover, parity testing | J21: Customer / Product Owner | K21: Solution Architect | N21: Unknown | R21: Parity card approved; deviations have owner decision | S21: New Legacy Finding or Target-only Requirement | T21: Added for Legacy Upgrade | U21: Imported; agent not recorded | V21: Added for Legacy Upgrade | W21: =IF(N21="Approved",IF(AND(G21<>"",J21<>"",K21<>"",L21<>"",L21<>"Architect draft",M21<>"",P21<>"",Q21<>""),"Yes","No"),IF(N21="Deferred",IF(AND(I21<>"",J21<>"",L21<>"",L21<>"Architect draft",M21<>"",P21<>"",S21<>""),"Yes","No"),"No")) -> No | X21: Feature-specific | Y21: first feature downstream delivery specification that implements this criterion | Z21: Exact rules are closed in the current feature/downstream delivery specification; once implemented, the outputs are synchronized back into the architecture.
A22: B | B22: B01 | C22: Operation | D22: Observability | E22: What logs, metrics, traces, correlation IDs, alerts and retention times are needed? | F22: Logging/APM stack, dashboards, incident response, health checks | J22: Solution Architect | K22: Customer / Product Owner; Technical Lead | N22: Unknown | R22: Minimum production observability set determined | S22: Incident, new SLO or new component | T22: Both CSVs | U22: Imported; agent not recorded | V22: Both CSVs | W22: =IF(N22="Approved",IF(AND(G22<>"",J22<>"",K22<>"",L22<>"",L22<>"Architect draft",M22<>"",P22<>"",Q22<>""),"Yes","No"),IF(N22="Deferred",IF(AND(I22<>"",J22<>"",L22<>"",L22<>"Architect draft",M22<>"",P22<>"",S22<>""),"Yes","No"),"No")) -> No | X22: Deployment & Operations | Y22: first operational slice that measures or changes this criterion | Z22: Checked as working slices and measurements appear; topology, SLO, or scale changes update NFR/ADR.
A23: B | B23: B02 | C23: Security | D23: Security operations | E23: What should be password policy, lockout, session timeout, audit events and incident handling? | F23: Identity configuration, audit storage, monitoring, runbooks | J23: Security / Compliance | K23: Solution Architect; Security / Compliance | N23: Unknown | R23: Settings and security scenarios are verifiable | S23: Security incident or policy change | T23: Our CSV | U23: Imported; agent not recorded | V23: Our CSV | W23: =IF(N23="Approved",IF(AND(G23<>"",J23<>"",K23<>"",L23<>"",L23<>"Architect draft",M23<>"",P23<>"",Q23<>""),"Yes","No"),IF(N23="Deferred",IF(AND(I23<>"",J23<>"",L23<>"",L23<>"Architect draft",M23<>"",P23<>"",S23<>""),"Yes","No"),"No")) -> No | X23: Identity & Access | Y23: 003-identity-and-access | Z23: It is specified in the feature/downstream delivery specification. The result is returned to the architecture and, if necessary, updates NFR/ADR..
A24: B | B24: B03 | C24: Reliability | D24: Backup | E24: What is the schedule, retention, off-site copies and frequency of restore rehearsal? | F24: Backup tooling, storage, runbooks, DR readiness | J24: Operations / DevOps | K24: Solution Architect; Operations / DevOps | N24: Unknown | R24: Successful documented verification of recovery | S24: Failure to restore test or change RPO/RTO | T24: Our CSV + RPO Claude | U24: Claude | V24: Our CSV + RPO Claude | W24: =IF(N24="Approved",IF(AND(G24<>"",J24<>"",K24<>"",L24<>"",L24<>"Architect draft",M24<>"",P24<>"",Q24<>""),"Yes","No"),IF(N24="Deferred",IF(AND(I24<>"",J24<>"",L24<>"",L24<>"Architect draft",M24<>"",P24<>"",S24<>""),"Yes","No"),"No")) -> No | X24: Deployment & Operations | Y24: first operational slice that measures or changes this criterion | Z24: Checked as working slices and measurements appear; topology, SLO, or scale changes update NFR/ADR.
A25: B | B25: B04 | C25: Quality. | D25: CI quality gates | E25: What formatting, analyzers, coverage, architecture tests and skipped tests prohibitions are required? | F25: CI pipeline, code quality tooling, test architecture | J25: Solution Architect | K25: Customer / Product Owner; Technical Lead | N25: Unknown | R25: There is an executable CI gate with approved thresholds | S25: Change of quality policy or repeated defect | T25: Our CSV | U25: Imported; agent not recorded | V25: Our CSV | W25: =IF(N25="Approved",IF(AND(G25<>"",J25<>"",K25<>"",L25<>"",L25<>"Architect draft",M25<>"",P25<>"",Q25<>""),"Yes","No"),IF(N25="Deferred",IF(AND(I25<>"",J25<>"",L25<>"",L25<>"Architect draft",M25<>"",P25<>"",S25<>""),"Yes","No"),"No")) -> No | X25: Deployment & Operations | Y25: 002-demo-deployment-baseline | Z25: Checked as working slices and measurements appear; topology, SLO, or scale changes update NFR/ADR.
A26: B | B26: A05 | C26: Data | D26: Data volume and growth | E26: What is the initial volume of databases and files, annual growth, peak growth and planning horizon? | F26: SQL sizing, storage, partitioning, archiving, object storage | J26: Customer / Product Owner | K26: Solution Architect | N26: Unknown | R26: There is a volume estimate and growth forecast | S26: Actual growth exceeds forecast | T26: Both CSVs | U26: Codex | V26: Owner decision in Codex session, 2026-08-11 | W26: =IF(N26="Approved",IF(AND(G26<>"",J26<>"",K26<>"",L26<>"",L26<>"Architect draft",M26<>"",P26<>"",Q26<>""),"Yes","No"),IF(N26="Deferred",IF(AND(I26<>"",J26<>"",L26<>"",L26<>"Architect draft",M26<>"",P26<>"",S26<>""),"Yes","No"),"No")) -> No | X26: Deployment & Operations | Y26: first operational slice that measures or changes this criterion | Z26: Checked as working slices and measurements appear; topology, SLO, or scale changes update NFR/ADR.
A27: B | B27: B05 | C27: Clients. | D27: Browsers and devices | E27: What browsers/versions, viewport, tablets, mobile and offline scripts are supported? | F27: SPA/SSR/PWA, CSS strategy, E2E matrix | J27: Solution Architect | K27: Customer / Product Owner; Technical Lead | N27: Unknown | R27: Approved support matrix | S27: New client channel or termination of browser support | T27: Both CSVs | U27: Imported; agent not recorded | V27: Both CSVs | W27: =IF(N27="Approved",IF(AND(G27<>"",J27<>"",K27<>"",L27<>"",L27<>"Architect draft",M27<>"",P27<>"",Q27<>""),"Yes","No"),IF(N27="Deferred",IF(AND(I27<>"",J27<>"",L27<>"",L27<>"Architect draft",M27<>"",P27<>"",S27<>""),"Yes","No"),"No")) -> No | X27: Feature-specific | Y27: first feature downstream delivery specification that implements this criterion | Z27: Exact rules are closed in the current feature/downstream delivery specification; once implemented, the outputs are synchronized back into the architecture.
A28: B | B28: B06 | C28: Clients. | D28: Accessibility | E28: Which WCAG level and which keyboard/screen-reader scripts are required? | F28: UI library, semantic markup, automated/manual accessibility tests | J28: Solution Architect | K28: Customer / Product Owner; Technical Lead | N28: Unknown | R28: WCAG scope and test matrix approved | S28: New regulatory or corporate standard | T28: Both CSVs; Grade B by default | U28: Imported; agent not recorded | V28: Both CSVs; Grade B by default | W28: =IF(N28="Approved",IF(AND(G28<>"",J28<>"",K28<>"",L28<>"",L28<>"Architect draft",M28<>"",P28<>"",Q28<>""),"Yes","No"),IF(N28="Deferred",IF(AND(I28<>"",J28<>"",L28<>"",L28<>"Architect draft",M28<>"",P28<>"",S28<>""),"Yes","No"),"No")) -> No | X28: Feature-specific | Y28: first feature downstream delivery specification that implements this criterion | Z28: Exact rules are closed in the current feature/downstream delivery specification; once implemented, the outputs are synchronized back into the architecture.
A29: B | B29: B07 | C29: Data | D29: File management | E29: What file types and sizes, antivirus, versioning, retention and access rights are needed? | F29: Local volume/object storage, scanning, CDN, authorization | J29: Customer / Product Owner | K29: Solution Architect | N29: Unknown | R29: There is an approved file policy | S29: New file type/size or external storage | T29: Our CSV | U29: Imported; agent not recorded | V29: Our CSV | W29: =IF(N29="Approved",IF(AND(G29<>"",J29<>"",K29<>"",L29<>"",L29<>"Architect draft",M29<>"",P29<>"",Q29<>""),"Yes","No"),IF(N29="Deferred",IF(AND(I29<>"",J29<>"",L29<>"",L29<>"Architect draft",M29<>"",P29<>"",S29<>""),"Yes","No"),"No")) -> No | X29: Data & Persistence | Y29: first data/files feature slice | Z29: Clarifies in the feature/downstream file delivery specification; actual storage, access and recovery after implementation return to the architecture.
A30: B | B30: B08 | C30: Data | D30: Data retention | E30: What are storage, archiving, legal holding, deletion and anonymization? | F30: Schema, jobs, archival storage, compliance | J30: Customer / Product Owner | K30: Solution Architect | N30: Unknown | R30: Conservation rules approved | S30: Changing the law or business policy | T30: Our CSV | U30: Imported; agent not recorded | V30: Our CSV | W30: =IF(N30="Approved",IF(AND(G30<>"",J30<>"",K30<>"",L30<>"",L30<>"Architect draft",M30<>"",P30<>"",Q30<>""),"Yes","No"),IF(N30="Deferred",IF(AND(I30<>"",J30<>"",L30<>"",L30<>"Architect draft",M30<>"",P30<>"",S30<>""),"Yes","No"),"No")) -> No | X30: Deployment & Operations | Y30: first operational slice that measures or changes this criterion | Z30: Checked as working slices and measurements appear; topology, SLO, or scale changes update NFR/ADR.
A31: B | B31: A09 | C31: Limitations | D31: System lifetime | E31: How long is the system designed and what is the platform update cycle expected? | F31: LTS-versions, replacement of components, upgrade strategy and technical debt | J31: Customer / Product Owner | K31: Solution Architect | N31: Unknown | R31: Operating horizon approved | S31: Extension of life or termination of component support | T31: CSV Claude | U31: Codex | V31: Owner decision in Codex session, 2026-08-11 | W31: =IF(N31="Approved",IF(AND(G31<>"",J31<>"",K31<>"",L31<>"",L31<>"Architect draft",M31<>"",P31<>"",Q31<>""),"Yes","No"),IF(N31="Deferred",IF(AND(I31<>"",J31<>"",L31<>"",L31<>"Architect draft",M31<>"",P31<>"",S31<>""),"Yes","No"),"No")) -> No | X31: Deployment & Operations | Y31: first operational slice that measures or changes this criterion | Z31: Checked as working slices and measurements appear; topology, SLO, or scale changes update NFR/ADR.
A32: B | B32: B09 | C32: Scaling | D32: Capacity forecast | E32: How will users, RPS, databases and files grow on the 1-3 year horizon? | F32: Scale thresholds, infrastructure roadmap, cost model | J32: Solution Architect | K32: Customer / Product Owner; Technical Lead | N32: Unknown | R32: There are forecasts and thresholds of architectural revision | S32: Reaching 70-80% of the agreed limit | T32: Our CSV | U32: Imported; agent not recorded | V32: Our CSV | W32: =IF(N32="Approved",IF(AND(G32<>"",J32<>"",K32<>"",L32<>"",L32<>"Architect draft",M32<>"",P32<>"",Q32<>""),"Yes","No"),IF(N32="Deferred",IF(AND(I32<>"",J32<>"",L32<>"",L32<>"Architect draft",M32<>"",P32<>"",S32<>""),"Yes","No"),"No")) -> No | X32: Deployment & Operations | Y32: first operational slice that measures or changes this criterion | Z32: Checked as working slices and measurements appear; topology, SLO, or scale changes update NFR/ADR.
... A39: B | B39: B16 | C39: Limitations | D39: Vendor lock-in and portability | E39: To what extent is it permissible to link to the provider/license and what data/components should be portable? | F39: Managed services, abstraction boundaries, export formats | J39: Operations / DevOps | K39: Solution Architect; Operations / DevOps | N39: Unknown | R39: Acceptable level of lock-in | S39: Change of provider, price or license | T39: CSV Claude | U39: Claude | V39: CSV Claude | W39: =IF(N39="Approved",IF(AND(G39<>"",J39<>"",K39<>"",L39<>"",L39<>"Architect draft",M39<>"",P39<>"",Q39<>""),"Yes","No"),IF(N39="Deferred",IF(AND(I39<>"",J39<>"",L39<>"",L39<>"Architect draft",M39<>"",P39<>"",S39<>""),"Yes","No"),"No")) -> No | X39: Deployment & Operations | Y39: first operational slice that measures or changes this criterion | Z39: Checked as working slices and measurements appear; topology, SLO, or scale changes update NFR/ADR.
A40: B | B40: A17 | C40: Localization | D40: Languages, time and formats | E40: What languages, time zones, currencies and date/number formats are supported? What's the fallback? | F40: Angular i18n, API contracts, time storage, scheduler, QA matrix | H40: Owner-approved target baseline | J40: Customer / Product Owner | K40: Solution Architect | N40: Unknown | R40: Locales and temporal model approved | S40: Addition of language, currency or region | T40: Owner decision + Manager regrade 2026-08-11 | U40: Owner / Manager | V40: Manager notes supplied to Codex, 2026-08-11 | W40: =IF(N40="Approved",IF(AND(G40<>"",J40<>"",K40<>"",L40<>"",L40<>"Architect draft",M40<>"",P40<>"",Q40<>""),"Yes","No"),IF(N40="Deferred",IF(AND(I40<>"",J40<>"",L40<>"",L40<>"Architect draft",M40<>"",P40<>"",S40<>""),"Yes","No"),"No")) -> No | X40: UI, Localization & Quality | Y40: first localized UI/API feature slice | Z40: Clarifies in the delivery specification affecting feature/downstream; implemented formats, resources and UTC contracts are returned to the architecture.
A41: B | B41: B17 | C41: Design | D41: Branding and theme | E41: Do you need themes, white-label, client styles, and multiple brands? | F41: Design system, tokens, CSS architecture, asset management | J41: Solution Architect | K41: Customer / Product Owner; Technical Lead | N41: Unknown | R41: There is a decision on the boundary of UI customizability | S41: New brand or white-label client | T41: CSV Claude | U41: Claude | V41: CSV Claude | W41: =IF(N41="Approved",IF(AND(G41<>"",J41<>"",K41<>"",L41<>"",L41<>"Architect draft",M41<>"",P41<>"",Q41<>""),"Yes","No"),IF(N41="Deferred",IF(AND(I41<>"",J41<>"",L41<>"",L41<>"Architect draft",M41<>"",P41<>"",S41<>""),"Yes","No"),"No")) -> No | X41: Feature-specific | Y41: first feature downstream delivery specification that implements this criterion | Z41: Exact rules are closed in the current feature/downstream delivery specification; once implemented, the outputs are synchronized back into the architecture.
A42: B | B42: B18 | C42: Delivery | D42: Deployment environments and release model | E42: What environments really exist, who manages them, how do deploy, migrate, rollback and smoke work? What production hosting/region/secrets has not yet been decided? | F42: Topology, CI/CD, configuration, secrets, EF migrations, rollback, downtime and operational ownership | H42: Operational constraint | J42: Customer / Product Owner | K42: Solution Architect; Operations / DevOps | N42: Unknown | R42: Demo runbook, migration, smoke and rollback are executable; production unknowns are recorded as a separate gate. | S42: Production hosting choice, multiple hosts, managed platform, compliance region or zero-downtime requirement | T42: Owner decision 2026-08-10; separated by Manager review 2026-08-11 | U42: Owner / Manager | V42: analysis/stages/stage-11/owner-remarks-004.md; Manager notes supplied to Codex, 2026-08-11 | W42: =IF(N42="Approved",IF(AND(G42<>"",J42<>"",K42<>"",L42<>"",L42<>"Architect draft",M42<>"",P42<>"",Q42<>""),"Yes","No"),IF(N42="Deferred",IF(AND(I42<>"",J42<>"",L42<>"",L42<>"Architect draft",M42<>"",P42<>"",S42<>""),"Yes","No"),"No")) -> No | X42: Deployment & Operations | Y42: 002-demo-deployment-baseline | Z42: Checked as working slices and measurements appear; topology, SLO, or scale changes update NFR/ADR.
A43: B | B43: A19 | C43: Limitations | D43: Technology, Licenses and Platform Restrictions | E43: Which stack is mandatory or prohibited? What versions, providers and licenses are allowed? | F43: Selection of platforms, libraries, hosting and managed services | J43: Solution Architect | K43: Customer / Product Owner; Technical Lead | N43: Unknown | R43: Owner decision on stack and restrictions n | S43: EOL component, change of license or corporate standard | T43: Both CSVs | U43: Codex | V43: Owner decision in Codex session, 2026-08-11 | W43: =IF(N43="Approved",IF(AND(G43<>"",J43<>"",K43<>"",L43<>"",L43<>"Architect draft",M43<>"",P43<>"",Q43<>""),"Yes","No"),IF(N43="Deferred",IF(AND(I43<>"",J43<>"",L43<>"",L43<>"Architect draft",M43<>"",P43<>"",S43<>""),"Yes","No"),"No")) -> No | X43: Foundation | Y43: 001-solution-foundation | Z43: Grade A captures the system solution. After each implementation, the architecture is checked again; change runtime, data, transactions, tenancy or deployment updates NFR/ADR.
A44: C | B44: C01 | C44: Scaling | D44: Multi-region | E44: Will work or rehabilitation be required in several regions? | F44: Global routing, replication, data residency | J44: Customer / Product Owner | K44: Solution Architect | N44: Unknown | R44: Measurable return trigger recorded | S44: Geography, SLA or DR require a second region | T44: Our CSV | U44: Imported; agent not recorded | V44: Our CSV | W44: =IF(N44="Approved",IF(AND(G44<>"",J44<>"",K44<>"",L44<>"",L44<>"Architect draft",M44<>"",P44<>"",Q44<>""),"Yes","No"),IF(N44="Deferred",IF(AND(I44<>"",J44<>"",L44<>"",L44<>"Architect draft",M44<>"",P44<>"",S44<>""),"Yes","No"),"No")) -> No | X44: Deployment & Operations | Y44: first operational slice that measures or changes this criterion | Z44: Checked as working slices and measurements appear; topology, SLO, or scale changes update NFR/ADR.
A45: C | B45: C02 | C45: Scaling | D45: Kubernetes | E45: Under what measurable conditions does a Docker Compose or one host cease to be sufficient? | F45: Orchestration, autoscaling, service discovery | J45: Solution Architect | K45: Customer / Product Owner; Technical Lead | N45: Unknown | R45: Not selected in advance; the implementation trigger is recorded | S45: replicas/services or operational load exceeds the threshold | T45: Our CSV; solution option | U45: Imported; agent not recorded | V45: Our CSV; solution option | W45: =IF(N45="Approved",IF(AND(G45<>"",J45<>"",K45<>"",L45<>"",L45<>"Architect draft",M45<>"",P45<>"",Q45<>""),"Yes","No"),IF(N45="Deferred",IF(AND(I45<>"",J45<>"",L45<>"",L45<>"Architect draft",M45<>"",P45<>"",S45<>""),"Yes","No"),"No")) -> No | X45: Deployment & Operations | Y45: first operational slice that measures or changes this criterion | Z45: Checked as working slices and measurements appear; topology, SLO, or scale changes update NFR/ADR.
A46: C | B46: C03 | C46: Integration | D46: Message broker | E46: Under what warranties, throughput or service separation will RabbitMQ/Kafka/another broker be required? | F46: Async delivery, service split, event processing | J46: Solution Architect | K46: Solution Architect; Operations / DevOps; Technical Lead | N46: Unknown | R46: Not selected in advance; the implementation trigger is recorded | S46: SQL outbox/worker no longer meets measurable requirements | T46: Our CSV; solution option | U46: Imported; agent not recorded | V46: Our CSV; solution option | W46: =IF(N46="Approved",IF(AND(G46<>"",J46<>"",K46<>"",L46<>"",L46<>"Architect draft",M46<>"",P46<>"",Q46<>""),"Yes","No"),IF(N46="Deferred",IF(AND(I46<>"",J46<>"",L46<>"",L46<>"Architect draft",M46<>"",P46<>"",S46<>""),"Yes","No"),"No")) -> No | X46: Integrations & Background Work | Y46: first integration/background-work slice | Z46: It is specified in the feature/downstream delivery specification. Real jobs, retries and contracts are verified after implementation and returned to the architecture.
...

Sheet System Diagram Gate
A1: System Architecture Gate — what must be decided before the high-level diagram
A2: DERIVED VIEW: populate from NFR Register, Technology Stack and Client Questionnaire. Feature mechanics belong in the downstream delivery specification backlog and must not block a system-level diagram.
A4: Total gates | B4: Ready | C4: Open | D4: Readiness | E4: Result | F4: Next step | G4: Source of truth | H4: Rule
A5: 12 | B5: 0 | C5: 12 | D5: 0 | E5: Open | F5: Complete architecture-shaping decisions | G5: NFR + Technology + Questionnaire | H5: High-level boundaries now; feature mechanics later
A7: Gate ID | B7: Diagram layer | C7: Required decision | D7: Governed source | E7: Current baseline | F7: Deferred to downstream delivery specification | G7: Status | H7: Diagram use
A8: SG-01 | B8: Scope | C8: System boundary and parity scope | D8: Record IDs | E8: To be decided | F8: Feature mechanics and exact contracts | G8: Open | H8: Required diagram layer/callout
A9: SG-02 | B9: Application | C9: Runtime containers and application shape | D9: Record IDs | E9: To be decided | F9: Feature mechanics and exact contracts | G9: Open | H9: Required diagram layer/callout
A10: SG-03 | B10: Tenancy | C10: Tenant and data-isolation boundary | D10: Record IDs | E10: To be decided | F10: Feature mechanics and exact contracts | G10: Open | H10: Required diagram layer/callout
A11: SG-04 | B11: Security | C11: Identity, trust boundary and high-level roles | D11: Record IDs | E11: To be decided | F11: Feature mechanics and exact contracts | G11: Open | H11: Required diagram layer/callout
A12: SG-05 | B12: Scale | C12: State ownership and horizontal-scale path | D12: Record IDs | E12: To be decided | F12: Feature mechanics and exact contracts | G12: Open | H12: Required diagram layer/callout
A13: SG-06 | B13: Data | C13: Transactional boundary and reliable side effects | D13: Record IDs | E13: To be decided | F13: Feature mechanics and exact contracts | G13: Open | H13: Required diagram layer/callout
A14: SG-07 | B14: Integrations | C14: External systems and protocol families | D14: Record IDs | E14: To be decided | F14: Feature mechanics and exact contracts | G14: Open | H14: Required diagram layer/callout
A15: SG-08 | B15: Background | C15: Scheduler/worker topology | D15: Record IDs | E15: To be decided | F15: Feature mechanics and exact contracts | G15: Open | H15: Required diagram layer/callout
A16: SG-09 | B16: Files | C16: High-level file/object storage boundary | D16: Record IDs | E16: To be decided | F16: Feature mechanics and exact contracts | G16: Open | H16: Required diagram layer/callout
A17: SG-10 | B17: Platform | C17: Ingress and deployment topology | D17: Record IDs | E17: To be decided | F17: Feature mechanics and exact contracts | G17: Open | H17: Required diagram layer/callout
A18: SG-11 | B18: NFR | C18: Capacity, latency, availability and recovery drivers | D18: Record IDs | E18: To be decided | F18: Feature mechanics and exact contracts | G18: Open | H18: Required diagram layer/callout
A19: SG-12 | B19: Technology | C19: Material technology baseline | D19: Record IDs | E19: To be decided | F19: Feature mechanics and exact contracts | G19: Open | H19: Required diagram layer/callout
A22: Downstream delivery / feature detail backlog — does not block the system diagram
A23: Feature area | B23: Deferred detail | C23: Closure stage | D23: Why it is not diagram-shaping
A24: Authentication | B24: Claims, MFA, lifecycle and provider configuration | C24: Feature downstream delivery specification | D24: Trust boundary already decided
A25: Files | B25: Limits, malware, retention, migration and API/UI states | C25: Feature downstream delivery specification | D25: Storage boundary is sufficient
A26: Integrations | B26: Consumers, schemas, auth, SLA and mappings | C26: Integration downstream delivery specification | D26: Adapter boundary is sufficient
A27: Jobs | B27: Schedules, retries, misfire, replay and runbooks | C27: Feature downstream delivery specification | D27: Worker topology is sufficient
A28: Security operations | B28: Provisioning, review, rotation, response and retention | C28: Security downstream delivery specification | D28: Operating detail
A29: Backup | B29: Product, cadence and restore commands | C29: Operations downstream delivery specification | D29: RPO/RTO are the driver
A30: Localization | B30: Catalogs, errors, formats and QA matrix | C30: Feature downstream delivery specification | D30: NFR, not a container

Sheet Team Capability
A1: Team Capability and Delivery Readiness
A2: First, we capture the actual competence and capacity of the company; then Technology Stack connects the selected technologies with the capability and the gap closing plan. The familiar stack is a risk and cost factor, not a substitute for NFR and owner decision.
A3: Order Stage 9: 1) current capability inventory → 2) NFR/constraints → 3) Technology Stack → 4) gap plan (training / hiring / partner / service managed) → 5) owner review.
A4: Total capacity. | C4: In fact valued | E4: Open gaps | G4: Ready for delivery | I4: Delivery readiness | K4: Inventory before the stack
A5: =COUNTA(A8:A100) -> 13 | C5: =COUNTIFS(C8:C100,"<>",E8:E100,"<>",E8:E100,"<>Unknown",F8:F100,"<>",G8:G100,"<>",H8:H100,"<>",P8:P100,"<>",P8:P100,"<>Unknown") -> 0 | E5: =COUNTIF(L8:L100,"Yes") -> 0 | G5: =COUNTIFS(L8:L100,"No",P8:P100,"<>",P8:P100,"<>Unknown")+COUNTIFS(L8:L100,"Yes",P8:P100,"Plan agreed")+COUNTIFS(L8:L100,"Yes",P8:P100,"Ready") -> 0 | I5: =IFERROR(G5/A5,0) -> 0 | K5: =IF(C5=A5,"Yeah, you can pick a stack.","No, assessment first.") -> No, assessment first.
A6: Stable ID | B6: Verified area of expertise | C6: People or team with this skill | D6: Real stack and practical experience | E6: Actual maturity now | F6: Confirmation of production experience | G6: Available time in full rate equivalent | H6: How many people have independent knowledge? | I6: What you need to know for the project | J6: What choice of architecture requires skill | K6: Minimum maturity for delivery | L6: The gap between current and required | M6: Training, hiring, partner or other plan | N6: Responsible for competence and plan | O6: When the gap should be closed | P6: Status of assessment and preparedness | Q6: Facts, references and explanations of the assessment | R6: Related Solutions and TECH-ID
A7: ID | B7: Capability domain | C7: Team / Available People | D7: Current Technologies and Experience | E7: Current Level | F7: Production evidence | G7: Available Capacity, FTE | H7: Bus factor | I7: Required Capability | J7: Selected Technology / Approach | K7: Required Level | L7: Gap | M7: Gap Closure Plan | N7: Capability owner | O7: Due Date | P7: Status | Q7: Evidence / Notes | R7: Related Decision / TECH-ID
A8: CAP-001 | B8: Product and domain expertise | E8: Unknown | K8: Unknown | L8: =IF(OR(E8="",E8="Unknown",K8="",K8="Unknown"),"Unknown",IF(MATCH(E8,'Reference Data'!$A$30:$A$35,0)>=MATCH(K8,'Reference Data'!$A$30:$A$35,0),"No","Yes")) -> Unknown | P8: Unknown
A9: CAP-002 | B9: Legacy engineering | E9: Unknown | K9: Unknown | L9: =IF(OR(E9="",E9="Unknown",K9="",K9="Unknown"),"Unknown",IF(MATCH(E9,'Reference Data'!$A$30:$A$35,0)>=MATCH(K9,'Reference Data'!$A$30:$A$35,0),"No","Yes")) -> Unknown | P9: Unknown
A10: CAP-003 | B10: Solution architecture | E10: Unknown | K10: Unknown | L10: =IF(OR(E10="",E10="Unknown",K10="",K10="Unknown"),"Unknown",IF(MATCH(E10,'Reference Data'!$A$30:$A$35,0)>=MATCH(K10,'Reference Data'!$A$30:$A$35,0),"No","Yes")) -> Unknown | P10: Unknown
A11: CAP-004 | B11: Backend engineering | E11: Unknown | K11: Unknown | L11: =IF(OR(E11="",E11="Unknown",K11="",K11="Unknown"),"Unknown",IF(MATCH(E11,'Reference Data'!$A$30:$A$35,0)>=MATCH(K11,'Reference Data'!$A$30:$A$35,0),"No","Yes")) -> Unknown | P11: Unknown
A12: CAP-005 | B12: Data engineering | E12: Unknown | K12: Unknown | L12: =IF(OR(E12="",E12="Unknown",K12="",K12="Unknown"),"Unknown",IF(MATCH(E12,'Reference Data'!$A$30:$A$35,0)>=MATCH(K12,'Reference Data'!$A$30:$A$35,0),"No","Yes")) -> Unknown | P12: Unknown
A13: CAP-006 | B13: Frontend engineering | E13: Unknown | K13: Unknown | L13: =IF(OR(E13="",E13="Unknown",K13="",K13="Unknown"),"Unknown",IF(MATCH(E13,'Reference Data'!$A$30:$A$35,0)>=MATCH(K13,'Reference Data'!$A$30:$A$35,0),"No","Yes")) -> Unknown | P13: Unknown
A14: CAP-007 | B14: Identity and application security | E14: Unknown | K14: Unknown | L14: =IF(OR(E14="",E14="Unknown",K14="",K14="Unknown"),"Unknown",IF(MATCH(E14,'Reference Data'!$A$30:$A$35,0)>=MATCH(K14,'Reference Data'!$A$30:$A$35,0),"No","Yes")) -> Unknown | P14: Unknown
A15: CAP-008 | B15: Platform and deployment | E15: Unknown | K15: Unknown | L15: =IF(OR(E15="",E15="Unknown",K15="",K15="Unknown"),"Unknown",IF(MATCH(E15,'Reference Data'!$A$30:$A$35,0)>=MATCH(K15,'Reference Data'!$A$30:$A$35,0),"No","Yes")) -> Unknown | P15: Unknown
A16: CAP-009 | B16: Integrations and background work | E16: Unknown | K16: Unknown | L16: =IF(OR(E16="",E16="Unknown",K16="",K16="Unknown"),"Unknown",IF(MATCH(E16,'Reference Data'!$A$30:$A$35,0)>=MATCH(K16,'Reference Data'!$A$30:$A$35,0),"No","Yes")) -> Unknown | P16: Unknown
A17: CAP-010 | B17: Quality and test automation | E17: Unknown | K17: Unknown | L17: =IF(OR(E17="",E17="Unknown",K17="",K17="Unknown"),"Unknown",IF(MATCH(E17,'Reference Data'!$A$30:$A$35,0)>=MATCH(K17,'Reference Data'!$A$30:$A$35,0),"No","Yes")) -> Unknown | P17: Unknown
A18: CAP-011 | B18: Observability | E18: Unknown | K18: Unknown | L18: =IF(OR(E18="",E18="Unknown",K18="",K18="Unknown"),"Unknown",IF(MATCH(E18,'Reference Data'!$A$30:$A$35,0)>=MATCH(K18,'Reference Data'!$A$30:$A$35,0),"No","Yes")) -> Unknown | P18: Unknown
A19: CAP-012 | B19: UX, accessibility and localization | E19: Unknown | K19: Unknown | L19: =IF(OR(E19="",E19="Unknown",K19="",K19="Unknown"),"Unknown",IF(MATCH(E19,'Reference Data'!$A$30:$A$35,0)>=MATCH(K19,'Reference Data'!$A$30:$A$35,0),"No","Yes")) -> Unknown | P19: Unknown
A20: CAP-013 | B20: Operations and support | E20: Unknown | K20: Unknown | L20: =IF(OR(E20="",E20="Unknown",K20="",K20="Unknown"),"Unknown",IF(MATCH(E20,'Reference Data'!$A$30:$A$35,0)>=MATCH(K20,'Reference Data'!$A$30:$A$35,0),"No","Yes")) -> Unknown | P20: Unknown

